<?xml version="1.0"?>
<robot xmlns:xacro="http://www.ros.org/wiki/xacro">
  <joint name="base_link_joint" type="fixed">
    <origin xyz="0.0 0.0 0.05" rpy="0.0 0.0 0.0"/>
    <parent link="base_footprint"/>
    <child link="base_link"/>
  </joint>

  <joint name="wheel_r_joint" type="continuous">
    <origin xyz="0.052 -0.095 -0.0025" rpy="0.0 0.0 0.0"/>
    <parent link="base_link"/>
    <child link="wheel_r_link"/>
    <axis xyz="0.0 1.0 0.0"/>
  </joint>

  <joint name="wheel_l_joint" type="continuous">
    <origin xyz="0.052 0.095 -0.0025" rpy="0.0 0.0 0.0"/>
    <parent link="base_link"/>
    <child link="wheel_l_link"/>
    <axis xyz="0.0 1.0 0.0"/>
  </joint>

  <joint name="caster_joint" type="fixed">
    <origin xyz="-0.09 0 -0.043" rpy="0.0 0.0 0.0"/>
    <parent link="base_link"/>
    <child link="caster_link"/>
  </joint>
</robot>
